<p>Throwing an exception from within a finally block will mask any exception which was previously thrown in the <code>try</code> or <code>catch</code>
block, and the maskedâ€™s exception message and stack trace will be lost.</p>
<h2>Noncompliant Code Example</h2>
<pre>
try
{
  /* some work which end up throwing an exception */
  throw new ArgumentException();
}
finally
{
  /* clean up */
  throw new InvalidOperationException();       // Noncompliant; will mask the ArgumentException
}
</pre>
<h2>Compliant Solution</h2>
<pre>
try
{
  /* some work which end up throwing an exception */
  throw new ArgumentException();
}
finally
{
  /* clean up */                       // Compliant
}
</pre>